Workbook

Sheet README
A1: Shared laundry – Milestone 1 research data
A2: Tenant survey (Tally form gDKWWN) · exported 2 Oct 2026 · prepared for slide updates
A4: Purpose | B4: All research data collected so far for the Milestone 1 pitch (Discover & Define), plus which slide each number belongs to.
A5: Sheets | B5: Survey Raw: every response, anonymised · Survey Summary: counts and % calculated from the raw sheet (formulas) · Slide Updates: which slide gets which number · Pending Evidence: what is still missing
A6: Survey | B6: 12 questions, ~3 minutes, built in Tally. Responses collected 1–2 Oct 2026 (UTC).
A7: Total responses | B7: 19 completed
A8: Target group | B8: People who share one washer with 5 or more others. 15 responses (all chose 5–6; nobody chose 7+).
A9: Excluded / reference only | B9: 1 response with 1–2 people per washer (screened out after Q3). 3 responses with 3–4 people answered the whole form because the screening rule did not fire; they are kept in the raw sheet but excluded from the target figures.
A10: Privacy | B10: Names, phone numbers and emails from Q12 are removed. Column 'Contact left' only shows whether a usable contact was given. Keep the original contacts inside the core team only.
A11: Caveats | B11: Small convenience sample (n = 15), mostly HDB room rentals (11) and condo rooms (4). Say 'n = 15' whenever a % is shown. Survey only: interview quotes and Round 2 follow-ups are not in this file yet.
A12: Price question wording | B12: 'What is the most your household would pay in total, once, for something that shows if the washer is free and reminds people to collect their laundry?'

Sheet Survey Raw
A1: Survey responses (anonymised)
A2: One row per response · Q7a–d and Q8 are 1–5 scores · 'In target' = shares one washer with 5+ people
A4: ID | B4: Submitted (UTC) | C4: In target? | D4: Q1 People sharing washer | E4: Q2 Where they live | F4: Q3 Laundry frequency | G4: Q4 Washer busy (past month) | H4: Q5 Others' laundry left (past month) | I4: Q6 Own laundry left >30 min (past month) | J4: Q7a Annoyance: washer busy | K4: Q7b Annoyance: others' laundry left | L4: Q7c Annoyance: whose load | M4: Q7d Annoyance: forget own | N4: Q8 Current way works (1–5) | O4: Q9 Workarounds today | P4: Q10 Messaging app | Q4: Q11 Max household pay (once) | R4: Contact left for follow-up?
A5: R01 | B5: 2026-10-01 02:21 | C5: =IF(D5="5–6","Yes",IF(D5="7 or more","Yes","No")) -> Yes | D5: 5–6 | E5: Room in an HDB flat | F5: 2–3 times a week | G5: 3–5 times | H5: 1–2 times | I5: 3–5 times | J5: 5 | K5: 5 | L5: 5 | M5: 2 | N5: 2 | O5: Walk over and check; Ask in a group chat; Set a phone timer | P5: WhatsApp | Q5: S$11–30 | R5: No
A6: R02 | B6: 2026-10-01 02:26 | C6: =IF(D6="5–6","Yes",IF(D6="7 or more","Yes","No")) -> Yes | D6: 5–6 | E6: Room in an HDB flat | F6: 2–3 times a week | G6: 3–5 times | H6: More than 5 times | I6: 1–2 times | J6: 4 | K6: 5 | L6: 4 | M6: 2 | N6: 3 | O6: Walk over and check; Ask in a group chat | P6: WhatsApp | Q6: S$11–30 | R6: No
A7: R03 | B7: 2026-10-01 02:26 | C7: =IF(D7="5–6","Yes",IF(D7="7 or more","Yes","No")) -> Yes | D7: 5–6 | E7: Room in an HDB flat | F7: 2–3 times a week | G7: 1–2 times | H7: 3–5 times | I7: 3–5 times | J7: 4 | K7: 1 | L7: 1 | M7: 4 | N7: 4 | O7: Nothing; Walk over and check | P7: WhatsApp | Q7: S$11–30 | R7: Yes
A8: R04 | B8: 2026-10-01 02:30 | C8: =IF(D8="5–6","Yes",IF(D8="7 or more","Yes","No")) -> Yes | D8: 5–6 | E8: Room in an HDB flat | F8: 2–3 times a week | G8: 1–2 times | H8: 1–2 times | I8: 1–2 times | J8: 4 | K8: 3 | L8: 3 | M8: 4 | N8: 4 | O8: Walk over and check; Other: move their laundry to the dryer / put it on top of the dryer | P8: WhatsApp | Q8: Up to S$10 | R8: Yes
A9: R05 | B9: 2026-10-01 02:31 | C9: =IF(D9="5–6","Yes",IF(D9="7 or more","Yes","No")) -> No | D9: 3–4 | E9: Other | F9: 4+ times a week | G9: Never | H9: Never | I9: More than 5 times | J9: 3 | K9: 3 | L9: 3 | M9: 2 | N9: 3 | O9: Nothing | P9: WhatsApp | Q9: S$0 | R9: No
A10: R06 | B10: 2026-10-01 02:39 | C10: =IF(D10="5–6","Yes",IF(D10="7 or more","Yes","No")) -> Yes | D10: 5–6 | E10: Room in an HDB flat | F10: 2–3 times a week | G10: 1–2 times | H10: 3–5 times | I10: 1–2 times | J10: 4 | K10: 1 | L10: 3 | M10: 4 | N10: 4 | O10: Walk over and check | P10: Other | Q10: Up to S$10 | R10: No
A11: R07 | B11: 2026-10-01 02:39 | C11: =IF(D11="5–6","Yes",IF(D11="7 or more","Yes","No")) -> Yes | D11: 5–6 | E11: Room in an HDB flat | F11: 2–3 times a week | G11: 1–2 times | H11: 1–2 times | I11: Never | J11: 2 | K11: 2 | L11: 2 | M11: 2 | N11: 4 | O11: Laundry schedule; Set a phone timer | P11: WhatsApp | Q11: S$31–50 | R11: No
A12: R08 | B12: 2026-10-01 02:51 | C12: =IF(D12="5–6","Yes",IF(D12="7 or more","Yes","No")) -> Yes | D12: 5–6 | E12: Room in a condo | F12: 2–3 times a week | G12: More than 5 times | H12: More than 5 times | I12: 1–2 times | J12: 3 | K12: 1 | L12: 1 | M12: 4 | N12: 4 | O12: Nothing | P12: WhatsApp | Q12: S$0 | R12: No
A13: R09 | B13: 2026-10-01 02:55 | C13: =IF(D13="5–6","Yes",IF(D13="7 or more","Yes","No")) -> Yes | D13: 5–6 | E13: Room in an HDB flat | F13: 2–3 times a week | G13: 1–2 times | H13: 3–5 times | I13: 1–2 times | J13: 4 | K13: 2 | L13: 5 | M13: 3 | N13: 3 | O13: Ask in a group chat; Set a phone timer; Walk over and check; Laundry schedule | P13: WhatsApp | Q13: Up to S$10 | R13: No
A14: R10 | B14: 2026-10-01 03:18 | C14: =IF(D14="5–6","Yes",IF(D14="7 or more","Yes","No")) -> Yes | D14: 5–6 | E14: Room in a condo | F14: 2–3 times a week | G14: 1–2 times | H14: 1–2 times | I14: Never | J14: 1 | K14: 1 | L14: 1 | M14: 1 | N14: 5 | O14: Ask in a group chat; Walk over and check | P14: Other | Q14: S$0 | R14: No
A15: R11 | B15: 2026-10-01 06:16 | C15: =IF(D15="5–6","Yes",IF(D15="7 or more","Yes","No")) -> Yes | D15: 5–6 | E15: Room in an HDB flat | F15: 2–3 times a week | G15: More than 5 times | H15: More than 5 times | I15: 3–5 times | J15: 4 | K15: 4 | L15: 2 | M15: 3 | N15: 3 | O15: Set a phone timer; Ask in a group chat | P15: Other | Q15: S$0 | R15: Yes
A16: R12 | B16: 2026-10-01 06:34 | C16: =IF(D16="5–6","Yes",IF(D16="7 or more","Yes","No")) -> Yes | D16: 5–6 | E16: Room in a condo | F16: 2–3 times a week | G16: 1–2 times | H16: 1–2 times | I16: 1–2 times | J16: 3 | K16: 3 | L16: 3 | M16: 4 | N16: 3 | O16: Walk over and check; Ask in a group chat | P16: WhatsApp | Q16: S$0 | R16: No
... A18: R14 | B18: 2026-10-01 09:50 | C18: =IF(D18="5–6","Yes",IF(D18="7 or more","Yes","No")) -> Yes | D18: 5–6 | E18: Room in a condo | F18: 4+ times a week | G18: 3–5 times | H18: 3–5 times | I18: 1–2 times | J18: 4 | K18: 4 | L18: 4 | M18: 4 | N18: 2 | O18: Walk over and check | P18: Other | Q18: S$0 | R18: No
A19: R15 | B19: 2026-10-01 12:48 | C19: =IF(D19="5–6","Yes",IF(D19="7 or more","Yes","No")) -> No | D19: 1–2 | E19: Other | F19: 2–3 times a week | R19: No
A20: R16 | B20: 2026-10-01 12:50 | C20: =IF(D20="5–6","Yes",IF(D20="7 or more","Yes","No")) -> No | D20: 3–4 | E20: Student hostel | F20: Once a week | G20: 3–5 times | H20: 1–2 times | I20: More than 5 times | J20: 3 | K20: 5 | L20: 5 | M20: 4 | N20: 3 | O20: Ask in a group chat; Walk over and check | P20: WhatsApp | Q20: Up to S$10 | R20: No
A21: R17 | B21: 2026-10-01 12:52 | C21: =IF(D21="5–6","Yes",IF(D21="7 or more","Yes","No")) -> No | D21: 3–4 | E21: Co-living | F21: 4+ times a week | G21: More than 5 times | H21: 1–2 times | I21: 1–2 times | J21: 4 | K21: 5 | L21: 5 | M21: 2 | N21: 5 | O21: Walk over and check; Ask in a group chat; Set a phone timer | P21: WhatsApp | Q21: Up to S$10 | R21: No
A22: R18 | B22: 2026-10-01 12:55 | C22: =IF(D22="5–6","Yes",IF(D22="7 or more","Yes","No")) -> Yes | D22: 5–6 | E22: Room in an HDB flat | F22: 2–3 times a week | G22: 3–5 times | H22: 3–5 times | I22: 1–2 times | J22: 4 | K22: 5 | L22: 4 | M22: 2 | N22: 2 | O22: Ask in a group chat; Set a phone timer | P22: WhatsApp | Q22: Up to S$10 | R22: No
A23: R19 | B23: 2026-10-02 02:03 | C23: =IF(D23="5–6","Yes",IF(D23="7 or more","Yes","No")) -> Yes | D23: 5–6 | E23: Room in an HDB flat | F23: 2–3 times a week | G23: 1–2 times | H23: 1–2 times | I23: More than 5 times | J23: 1 | K23: 1 | L23: 1 | M23: 1 | N23: 5 | O23: Laundry schedule | P23: Other | Q23: S$0 | R23: No

Sheet Survey Summary
A1: Survey summary – target group (5+ people per washer)
A2: All numbers are formulas on 'Survey Raw' filtered by In target = Yes
A4: Target respondents (n) | B4: =COUNTIF('Survey Raw'!$C$5:$C$23,"Yes") -> 15
A6: Q2 Where they live | B6: Count | C6: % of n
A7: Room in an HDB flat | B7: =COUNTIFS('Survey Raw'!$C$5:$C$23,"Yes",'Survey Raw'!$E$5:$E$23,"Room in an HDB flat") -> 11 | C7: =IF($B$4=0,0,B7/$B$4) -> 0.73333333
A8: Room in a condo | B8: =COUNTIFS('Survey Raw'!$C$5:$C$23,"Yes",'Survey Raw'!$E$5:$E$23,"Room in a condo") -> 4 | C8: =IF($B$4=0,0,B8/$B$4) -> 0.26666667
A9: Co-living | B9: =COUNTIFS('Survey Raw'!$C$5:$C$23,"Yes",'Survey Raw'!$E$5:$E$23,"Co-living") -> 0 | C9: =IF($B$4=0,0,B9/$B$4) -> 0
A10: Student hostel | B10: =COUNTIFS('Survey Raw'!$C$5:$C$23,"Yes",'Survey Raw'!$E$5:$E$23,"Student hostel") -> 0 | C10: =IF($B$4=0,0,B10/$B$4) -> 0
A11: Other | B11: =COUNTIFS('Survey Raw'!$C$5:$C$23,"Yes",'Survey Raw'!$E$5:$E$23,"Other") -> 0 | C11: =IF($B$4=0,0,B11/$B$4) -> 0
A13: Q4 Washer busy when needed (past month) | B13: Count | C13: % of n
A14: Never | B14: =COUNTIFS('Survey Raw'!$C$5:$C$23,"Yes",'Survey Raw'!$G$5:$G$23,"Never") -> 0 | C14: =IF($B$4=0,0,B14/$B$4) -> 0
A15: 1–2 times | B15: =COUNTIFS('Survey Raw'!$C$5:$C$23,"Yes",'Survey Raw'!$G$5:$G$23,"1–2 times") -> 8 | C15: =IF($B$4=0,0,B15/$B$4) -> 0.53333333
A16: 3–5 times | B16: =COUNTIFS('Survey Raw'!$C$5:$C$23,"Yes",'Survey Raw'!$G$5:$G$23,"3–5 times") -> 5 | C16: =IF($B$4=0,0,B16/$B$4) -> 0.33333333
A17: More than 5 times | B17: =COUNTIFS('Survey Raw'!$C$5:$C$23,"Yes",'Survey Raw'!$G$5:$G$23,"More than 5 times") -> 2 | C17: =IF($B$4=0,0,B17/$B$4) -> 0.13333333
A19: Q5 Found others' finished laundry left (past month) | B19: Count | C19: % of n
A20: Never | B20: =COUNTIFS('Survey Raw'!$C$5:$C$23,"Yes",'Survey Raw'!$H$5:$H$23,"Never") -> 0 | C20: =IF($B$4=0,0,B20/$B$4) -> 0
A21: 1–2 times | B21: =COUNTIFS('Survey Raw'!$C$5:$C$23,"Yes",'Survey Raw'!$H$5:$H$23,"1–2 times") -> 6 | C21: =IF($B$4=0,0,B21/$B$4) -> 0.4
A22: 3–5 times | B22: =COUNTIFS('Survey Raw'!$C$5:$C$23,"Yes",'Survey Raw'!$H$5:$H$23,"3–5 times") -> 6 | C22: =IF($B$4=0,0,B22/$B$4) -> 0.4
A23: More than 5 times | B23: =COUNTIFS('Survey Raw'!$C$5:$C$23,"Yes",'Survey Raw'!$H$5:$H$23,"More than 5 times") -> 3 | C23: =IF($B$4=0,0,B23/$B$4) -> 0.2
A25: Q6 Left own laundry >30 min (past month) | B25: Count | C25: % of n
A26: Never | B26: =COUNTIFS('Survey Raw'!$C$5:$C$23,"Yes",'Survey Raw'!$I$5:$I$23,"Never") -> 2 | C26: =IF($B$4=0,0,B26/$B$4) -> 0.13333333
A27: 1–2 times | B27: =COUNTIFS('Survey Raw'!$C$5:$C$23,"Yes",'Survey Raw'!$I$5:$I$23,"1–2 times") -> 9 | C27: =IF($B$4=0,0,B27/$B$4) -> 0.6
A28: 3–5 times | B28: =COUNTIFS('Survey Raw'!$C$5:$C$23,"Yes",'Survey Raw'!$I$5:$I$23,"3–5 times") -> 3 | C28: =IF($B$4=0,0,B28/$B$4) -> 0.2
A29: More than 5 times | B29: =COUNTIFS('Survey Raw'!$C$5:$C$23,"Yes",'Survey Raw'!$I$5:$I$23,"More than 5 times") -> 1 | C29: =IF($B$4=0,0,B29/$B$4) -> 0.066666667
A31: Key rates (target group) | B31: Count | C31: % of n
A32: Washer busy at least once | B32: =$B$4-COUNTIFS('Survey Raw'!$C$5:$C$23,"Yes",'Survey Raw'!$G$5:$G$23,"Never") -> 15 | C32: =IF($B$4=0,0,B32/$B$4) -> 1
A33: Washer busy 3+ times | B33: =COUNTIFS('Survey Raw'!$C$5:$C$23,"Yes",'Survey Raw'!$G$5:$G$23,"3–5 times")+COUNTIFS('Survey Raw'!$C$5:$C$23,"Yes",'Survey Raw'!$G$5:$G$23,"More than 5 times") -> 7 | C33: =IF($B$4=0,0,B33/$B$4) -> 0.46666667
A34: Others' laundry left at least once | B34: =$B$4-COUNTIFS('Survey Raw'!$C$5:$C$23,"Yes",'Survey Raw'!$H$5:$H$23,"Never") -> 15 | C34: =IF($B$4=0,0,B34/$B$4) -> 1
A35: Others' laundry left 3+ times | B35: =COUNTIFS('Survey Raw'!$C$5:$C$23,"Yes",'Survey Raw'!$H$5:$H$23,"3–5 times")+COUNTIFS('Survey Raw'!$C$5:$C$23,"Yes",'Survey Raw'!$H$5:$H$23,"More than 5 times") -> 9 | C35: =IF($B$4=0,0,B35/$B$4) -> 0.6
A36: Left own laundry at least once | B36: =$B$4-COUNTIFS('Survey Raw'!$C$5:$C$23,"Yes",'Survey Raw'!$I$5:$I$23,"Never") -> 13 | C36: =IF($B$4=0,0,B36/$B$4) -> 0.86666667
A37: Left own laundry 3+ times | B37: =COUNTIFS('Survey Raw'!$C$5:$C$23,"Yes",'Survey Raw'!$I$5:$I$23,"3–5 times")+COUNTIFS('Survey Raw'!$C$5:$C$23,"Yes",'Survey Raw'!$I$5:$I$23,"More than 5 times") -> 4 | C37: =IF($B$4=0,0,B37/$B$4) -> 0.26666667
A39: Q7 Annoyance (1–5) | B39: Average | C39: Count 4–5 | D39: % 4–5
A40: Washer busy when I need it | B40: =AVERAGEIF('Survey Raw'!$C$5:$C$23,"Yes",'Survey Raw'!$J$5:$J$23) -> 3.2666667 | C40: =COUNTIFS('Survey Raw'!$C$5:$C$23,"Yes",'Survey Raw'!$J$5:$J$23,">=4") -> 9 | D40: =IF($B$4=0,0,C40/$B$4) -> 0.6
A41: Someone's finished laundry left | B41: =AVERAGEIF('Survey Raw'!$C$5:$C$23,"Yes",'Survey Raw'!$K$5:$K$23) -> 2.8 | C41: =COUNTIFS('Survey Raw'!$C$5:$C$23,"Yes",'Survey Raw'!$K$5:$K$23,">=4") -> 6 | D41: =IF($B$4=0,0,C41/$B$4) -> 0.4
A42: Don't know whose laundry it is | B42: =AVERAGEIF('Survey Raw'!$C$5:$C$23,"Yes",'Survey Raw'!$L$5:$L$23) -> 2.9333333 | C42: =COUNTIFS('Survey Raw'!$C$5:$C$23,"Yes",'Survey Raw'!$L$5:$L$23,">=4") -> 6 | D42: =IF($B$4=0,0,C42/$B$4) -> 0.4
A43: I forget my own laundry | B43: =AVERAGEIF('Survey Raw'!$C$5:$C$23,"Yes",'Survey Raw'!$M$5:$M$23) -> 2.8 | C43: =COUNTIFS('Survey Raw'!$C$5:$C$23,"Yes",'Survey Raw'!$M$5:$M$23,">=4") -> 6 | D43: =IF($B$4=0,0,C43/$B$4) -> 0.4
A44: Q8 Current way works (1 = very badly, 5 = very well) | B44: =AVERAGEIF('Survey Raw'!$C$5:$C$23,"Yes",'Survey Raw'!$N$5:$N$23) -> 3.4666667 | C44: =COUNTIFS('Survey Raw'!$C$5:$C$23,"Yes",'Survey Raw'!$N$5:$N$23,"<=3") -> 7 | D44: =IF($B$4=0,0,C44/$B$4) -> 0.46666667 | E44: ← count/% scoring 3 or less
A46: Q9 Workarounds (multi-select) | B46: Count | C46: % of n
A47: Walk over and check | B47: =COUNTIFS('Survey Raw'!$C$5:$C$23,"Yes",'Survey Raw'!$O$5:$O$23,"*Walk over and check*") -> 10 | C47: =IF($B$4=0,0,B47/$B$4) -> 0.66666667
A48: Ask in a group chat | B48: =COUNTIFS('Survey Raw'!$C$5:$C$23,"Yes",'Survey Raw'!$O$5:$O$23,"*Ask in a group chat*") -> 8 | C48: =IF($B$4=0,0,B48/$B$4) -> 0.53333333
...

Sheet Slide Updates
A1: Where each finding goes in the pitch deck
A2: Slide numbers follow the current 22-slide deck · Status: 'Update to n=15' = on the slide with n=14 figures, replace with this value, Pending = needs interview data
A4: Slide | B4: Slide title | C4: Field / box | D4: Value to show | E4: Source | F4: Status
A5: 3 | B5: Three common pains, and how people cope today | C5: Evidence – washer busy | D5: 15/15 hit it last month · 47% 3+ times · 60% rate it 4–5 of 5 | E5: Survey Summary | F5: Update to n=15
A6: 3 | C6: Evidence – others' laundry left | D6: 15/15 found it · 60% 3+ times a month | E6: Survey Summary | F6: Update to n=15
A7: 3 | C7: Evidence – whose load | D7: 40% rate it 4–5 of 5 + one interview quote | E7: Survey + interviews | F7: Pending quote
A8: 3 | C8: Footer – workarounds | D8: Walk over 67% · group chat 53% · phone timer 40% | E8: Survey Summary | F8: Update to n=15
A9: 4 | B9: Final HMW | C9: Why it matters | D9: All 15 found the washer busy last month (47% 3+ times); 60% find others' finished load left 3+ times a month | E9: Survey Summary | F9: Update to n=15
A10: 4 | C10: Opportunity | D10: One sourced figure on room rentals / co-living in Singapore | E10: Desk research | F10: Pending
A11: 6 | B11: Who we engaged | C11: Primary users | D11: 15 survey + [n] interviews · Busy machine most annoying, left laundry most frequent | E11: Survey + interviews | F11: Partly
A12: 6 | C12: Lead users, buyers, operators, non-adopters | D12: # people and key takeaway per group | E12: Interviews | F12: Pending
A13: 8 | B13: Three insights | C13: Insight cards + quotes | D13: Insight statements (needs… BUT… because) with verbatim quotes | E13: Interviews | F13: Pending
A14: 9 | B14: We went back to the same people | C14: Before → after, row 1 | D14: Assumed tenants would pay → 10/15 would pay S$10 or less, 6 nothing → test landlord as first buyer | E14: Survey | F14: Update to n=15
A15: 9 | C15: Rounds timeline, row 2, pivot | D15: Round 1 and Round 2 dates, revisited participants, one pivot quote | E15: Interviews | F15: Pending
A16: 11 | B16: Benchmark | C16: Non-consumption row | D16: Manual workarounds: walk over / chat / timer with the % above | E16: Survey | F16: To add
A17: 17 | B17: What users need, ranked | C17: Ranking + channel + price | D17: Rank by annoyance; WhatsApp 10 of 15; 10 of 15 pay S$10 or less | E17: Survey Summary | F17: Update to n=15
A18: 19 | B18: Who feels it first | C18: Users card | D18: All 15 surveyed hit a busy machine last month | E18: Survey | F18: Update to n=15
A19: 20 | B19: Willingness to pay | C19: Who pays + test step 2 | D19: Tenant price split: 40% S$0 · 27% up to S$10 · 33% S$11+ | E19: Survey Summary | F19: Update to n=15
A20: 20 | C20: Price hypothesis, anchors, BOM | D20: Landlord answer, smart plug price, bill of materials | E20: Interview + desk research | F20: Pending

Sheet Pending Evidence
A1: Evidence still missing before the pitch
A2: Fill the yellow cells as data comes in
A4: # | B4: What | C4: Needed for | D4: Method | E4: Notes
A5: 1 | B5: Tenant interviews (Round 1), with quotes | C5: Insights, engagement table, HMW evidence | D5: Interview guide Part A
A6: 2 | B6: Landlord / master tenant interview(s) | C6: Buyer, WTP, segment | D6: Interview guide Part B | E6: Test landlord as first buyer
A7: 3 | B7: Round 2 follow-ups with the 4 survey contacts and interviewees | C7: Repeated engagement, pivot | D7: Interview guide Round 2 | E7: Contacts held by core team only
A8: 4 | B8: AEIOU observation of a shared washer (photos) | C8: AEIOU slide | D8: On-site observation
A9: 5 | B9: Sourced figure on room rentals / co-living in Singapore | C9: Final HMW – opportunity | D9: Desk research
A10: 6 | B10: Benchmark values for each alternative (price, time, effort) | C10: Benchmark, perceptual map, strategy canvas | D10: Desk research + survey
A11: 7 | B11: Bill of materials and smart plug price | C11: WTP anchors | D11: Desk research
A12: 8 | B12: Check Tally screening rule (3–4 respondents passed it) | C12: Clean data | D12: Tally settings
